Workbook
Name AbilityList: [1]Math!$A$48:$A$98
Name AbilityListNoAttributes: [1]Math!$A$48:$A$79
Name AbilityRating: [1]Math!$D$48:$D$98
Name AbilityStatus: [1]Math!$B$105:$B$129
Name AbilityTypeFinal: [1]Math!$J$36:$J$39
Name AbilityTypeSplat: [1]Math!$N$47:$N$63
Name AbilityTypeTable: [1]Math!$O$47:$Q$63
Name AltChargen: [1]Character!$U$2
Name Anima: [1]Data!$D$11:$D$14
Name ArmorStats: [1]Data!$O$21:$S$27
Name ArmorTags: [1]Data!$M$6:$M$10
Name ArmorTypes: [1]Data!$L$2:$M$4
Name AttributeDexterity: [1]Math!$D$86
Name AttributePerception: [1]Math!$D$91
Name AttributeStamina: [1]Math!$D$87
Name AttributeStrength: [1]Math!$D$85
Name AttributeTypeFinal: [1]Math!$K$36:$K$38
Name AttributeTypeSplat: [1]Math!$K$27:$N$27
Name AttributeTypeTable: [1]Math!$K$28:$N$31
Name AttributeWits: [1]Math!$D$93
Name BGDrillType: [1]Data!$Q$37:$Q$39
Name BGMightAttack: [1]Data!$R$41:$R$44
Name BGMightDamage: [1]Data!$S$41:$S$44
Name BGMightDefense: [1]Data!$T$41:$T$44
Name BGMightValue: [1]Data!$Q$41:$Q$44
Name BPCostSplat: [1]Data!$W$27:$AG$27
Name BPCostTable: [1]Data!$W$28:$AG$41
Name BPCostType: [1]Data!$V$28:$V$41
Name CasAttributeFlag: [1]Math!$K$33
Name Caste: [1]Character!$O$3
Name CasteCount: [1]Math!$O$46
Name CasteLookup: [1]Data!$G$29:$H$37
Name Castes: [1]Data!$G$23:$G$27
Name CharacterMerits: [1]Character!$A$26:$H$57
Name ChargenAmount: [2]Data!$V$3:$AL$13
Name ChargenDropdown: [1]Data!$X$44:$X$51
Name ChargenHeader: [2]Data!$V$2:$AL$2
Name CharmData: '[1]Charm List'!$A$2:$L$3453
Name CharmDataAbility: '[1]Charm List'!$H$2:$H$4004
Name CharmDataAbilPreq: '[1]Charm List'!$I$2:$I$4004
Name CharmDataAspect: '[1]Charm List'!$K$2:$K$4004
Name CharmDataCost: '[1]Charm List'!$B$2:$B$4004
Name CharmDataDesc: '[1]Charm List'!$F$2:$F$4004
Name CharmDataDuration: '[1]Charm List'!$E$2:$E$4004
Name CharmDataEssPreq: '[1]Charm List'!$J$2:$J$4004
Name CharmDataKeyword: '[1]Charm List'!$D$2:$D$4004
Name CharmDataName: '[1]Charm List'!$A$2:$A$4004
Name CharmDataPage: '[1]Charm List'!$G$2:$G$4004
Name CharmDataType: '[1]Charm List'!$C$2:$C$4004
Name CharmSelectionCategory: [2]Charms!$A$3:$A$202
Name CharmSelectionEssence: [2]Charms!$J$3:$J$202
Name CharmSelectionName: [2]Charms!$B$3:$B$202
Name CustomCharmCategory: [2]Data!$R$47:$R$79
Name CustomCharmCategoryDropdown: [1]Data!$R$47:$R$79
Name DataCharmsAll: Solarlist!$B:$M
Name DataCharmsAll: Siderial!$B:$S
Name DataCharmsAllType: Solarlist!$A:$A
Name DataCharmsAllType: Siderial!$A:$A
Name DataSpellHeader: [1]Spells!$B$1:$H$1
Name DataSpellInfo: [1]Spells!$B:$H

Sheet timeline
A1: Event | B1: First Age | C1: Autochthonia | D1: Realm
A2: History begins | B2: 0 | C2: -121 | D2: -4448
A3: Autochthon leaves Creation | B3: 121 | C3: 0 | D3: -4327 | E3: =D3-B3 -> -4448
A4: Start of Time of Cascading Years | B4: 2325 | C4: 2204 | D4: -2123 | E4: =D4-B4 -> -4448
A5: End of Time of Cascading Years | B5: 2543 | C5: 2204 | D5: -1906 | E5: =D5-B5 -> -4449 | H5: что | I5: прошло
A6: The "present" for Dreams of the First Age campaigns | B6: 3516 | D6: -933 | E6: =D6-B6 -> -4449 | G6: 1807 | H6: ДР Ингоша СебКогти | I6: =$B$10-G6 -> 3410
A7: usurpation | B7: =4449+D7 -> 3699 | D7: -750 | G7: 3255 | H7: Левиафан | I7: =$B$10-G7 -> 1962
A8: shogunate | B8: =4449+D8 -> 3749 | D8: -700 | G8: 1 | H8: Чейоп Кеджак | I8: =$B$10-G8 -> 5216
A9: Realm Begins | B9: 4449 | C9: 4110 | D9: 0 | E9: =D9-B9 -> -4449 | I9: =$B$10-G9 -> 5217
A10: Present | B10: 5217 | C10: 4878 | D10: 768 | E10: =D10-B10 -> -4449 | G10: 3475 | I10: =$B$10-G10 -> 1742
I11: =$B$10-G11 -> 5217

Sheet solar tabs
A1: Type | B1: Solar | T1: Type | U1: Solar
A2: Ess. Min | B2: 1 | T2: Ess. Min | U2: (Все)
A4: Названия строк | B4: Количество по полю Name | T4: Aspect Space | U4: Ability | X4: dawn | Y4: zenith | Z4: twilight | AA4: night | AB4: eclipse | AD4: Aspect Space | AE4: Ability
A5: Archery | B5: 7 | T5: dawn | U5: Archery | V5: 1 | W5: dawn | X5: =IF($W5=X$4,COUNTIF($T:$T,$W5),COUNTIF($T:$T,$W5&", "&X$4)+COUNTIF($T:$T,X$4&", "&$W5)) -> 4 | Y5: =IF($W5=Y$4,COUNTIF($T:$T,$W5),COUNTIF($T:$T,$W5&", "&Y$4)+COUNTIF($T:$T,Y$4&", "&$W5)) -> 2 | Z5: =IF($W5=Z$4,COUNTIF($T:$T,$W5),COUNTIF($T:$T,$W5&", "&Z$4)+COUNTIF($T:$T,Z$4&", "&$W5)) -> 0 | AA5: =IF($W5=AA$4,COUNTIF($T:$T,$W5),COUNTIF($T:$T,$W5&", "&AA$4)+COUNTIF($T:$T,AA$4&", "&$W5)) -> 2 | AB5: =IF($W5=AB$4,COUNTIF($T:$T,$W5),COUNTIF($T:$T,$W5&", "&AB$4)+COUNTIF($T:$T,AB$4&", "&$W5)) -> 0 | AD5: dawn | AE5: Archery | AF5: 1 | AG5: =CONCATENATE("|",AE6,"|","cfs","|",5,"|","3+2b|") -> |Athletics|cfs|5|3+2b|
A6: 2 | B6: 1 | T6: dawn | U6: Brawl | V6: 2 | W6: zenith | X6: =IF($W6=X$4,COUNTIF($T:$T,$W6),COUNTIF($T:$T,$W6&", "&X$4)+COUNTIF($T:$T,X$4&", "&$W6)) -> 2 | Y6: =IF($W6=Y$4,COUNTIF($T:$T,$W6),COUNTIF($T:$T,$W6&", "&Y$4)+COUNTIF($T:$T,Y$4&", "&$W6)) -> 2 | Z6: =IF($W6=Z$4,COUNTIF($T:$T,$W6),COUNTIF($T:$T,$W6&", "&Z$4)+COUNTIF($T:$T,Z$4&", "&$W6)) -> 2 | AA6: =IF($W6=AA$4,COUNTIF($T:$T,$W6),COUNTIF($T:$T,$W6&", "&AA$4)+COUNTIF($T:$T,AA$4&", "&$W6)) -> 1 | AB6: =IF($W6=AB$4,COUNTIF($T:$T,$W6),COUNTIF($T:$T,$W6&", "&AB$4)+COUNTIF($T:$T,AB$4&", "&$W6)) -> 1 | AD6: zenith, night | AE6: Athletics | AF6: 13 | AG6: =CONCATENATE("|",AE7,"|","cfs","|",5,"|","3+2b|") -> |Awareness|cfs|5|3+2b|
A7: Wise Arrow | B7: 1 | T7: dawn | U7: Melee | V7: 3 | W7: twilight | X7: =IF($W7=X$4,COUNTIF($T:$T,$W7),COUNTIF($T:$T,$W7&", "&X$4)+COUNTIF($T:$T,X$4&", "&$W7)) -> 0 | Y7: =IF($W7=Y$4,COUNTIF($T:$T,$W7),COUNTIF($T:$T,$W7&", "&Y$4)+COUNTIF($T:$T,Y$4&", "&$W7)) -> 2 | Z7: =IF($W7=Z$4,COUNTIF($T:$T,$W7),COUNTIF($T:$T,$W7&", "&Z$4)+COUNTIF($T:$T,Z$4&", "&$W7)) -> 2 | AA7: =IF($W7=AA$4,COUNTIF($T:$T,$W7),COUNTIF($T:$T,$W7&", "&AA$4)+COUNTIF($T:$T,AA$4&", "&$W7)) -> 1 | AB7: =IF($W7=AB$4,COUNTIF($T:$T,$W7),COUNTIF($T:$T,$W7&", "&AB$4)+COUNTIF($T:$T,AB$4&", "&$W7)) -> 3 | AD7: dawn, night | AE7: Awareness | AF7: 7 | AG7: =CONCATENATE("|",AE8,"|","cfs","|",5,"|","3+2b|") -> |Brawl|cfs|5|3+2b|
A8: 3 | B8: 3 | T8: dawn | U8: Thrown | V8: 4 | W8: night | X8: =IF($W8=X$4,COUNTIF($T:$T,$W8),COUNTIF($T:$T,$W8&", "&X$4)+COUNTIF($T:$T,X$4&", "&$W8)) -> 2 | Y8: =IF($W8=Y$4,COUNTIF($T:$T,$W8),COUNTIF($T:$T,$W8&", "&Y$4)+COUNTIF($T:$T,Y$4&", "&$W8)) -> 1 | Z8: =IF($W8=Z$4,COUNTIF($T:$T,$W8),COUNTIF($T:$T,$W8&", "&Z$4)+COUNTIF($T:$T,Z$4&", "&$W8)) -> 1 | AA8: =IF($W8=AA$4,COUNTIF($T:$T,$W8),COUNTIF($T:$T,$W8&", "&AA$4)+COUNTIF($T:$T,AA$4&", "&$W8)) -> 1 | AB8: =IF($W8=AB$4,COUNTIF($T:$T,$W8),COUNTIF($T:$T,$W8&", "&AB$4)+COUNTIF($T:$T,AB$4&", "&$W8)) -> 3 | AD8: dawn | AE8: Brawl | AF8: 2 | AG8: =CONCATENATE("|",AE9,"|","cfs","|",5,"|","3+2b|") -> |Bureaucr.|cfs|5|3+2b|
A9: Phantom Arrow Technique | B9: 1 | T9: dawn, zenith | U9: Resistan. | V9: 5 | W9: eclipse | X9: =IF($W9=X$4,COUNTIF($T:$T,$W9),COUNTIF($T:$T,$W9&", "&X$4)+COUNTIF($T:$T,X$4&", "&$W9)) -> 0 | Y9: =IF($W9=Y$4,COUNTIF($T:$T,$W9),COUNTIF($T:$T,$W9&", "&Y$4)+COUNTIF($T:$T,Y$4&", "&$W9)) -> 1 | Z9: =IF($W9=Z$4,COUNTIF($T:$T,$W9),COUNTIF($T:$T,$W9&", "&Z$4)+COUNTIF($T:$T,Z$4&", "&$W9)) -> 3 | AA9: =IF($W9=AA$4,COUNTIF($T:$T,$W9),COUNTIF($T:$T,$W9&", "&AA$4)+COUNTIF($T:$T,AA$4&", "&$W9)) -> 3 | AB9: =IF($W9=AB$4,COUNTIF($T:$T,$W9),COUNTIF($T:$T,$W9&", "&AB$4)+COUNTIF($T:$T,AB$4&", "&$W9)) -> 1 | AD9: twilight, eclipse | AE9: Bureaucr. | AF9: 17 | AG9: =CONCATENATE("|",AE10,"|","cfs","|",5,"|","3+2b|") -> |Craft|cfs|5|3+2b|
A10: Sight Without Eyes | B10: 1 | T10: dawn, zenith | U10: War | V10: 6 | AD10: twilight | AE10: Craft | AF10: 15 | AG10: =CONCATENATE("|",AE11,"|","cfs","|",5,"|","3+2b|") -> |Dodge|cfs|5|3+2b|
A11: Trance of Unhesitating Speed | B11: 1 | T11: dawn, night | U11: Awareness | V11: 7 | AD11: dawn, night | AE11: Dodge | AF11: 8 | AG11: =CONCATENATE("|",AE12,"|","cfs","|",5,"|","3+2b|") -> |Integrity|cfs|5|3+2b|
A12: 4 | B12: 3 | T12: dawn, night | U12: Dodge | V12: 8 | AD12: zenith, twilight | AE12: Integrity | AF12: 11 | AG12: =CONCATENATE("|",AE13,"|","cfs","|",5,"|","3+2b|") -> |Investig.|cfs|5|3+2b|
A13: Blood Without Balance | B13: 1 | T13: zenith | U13: Perform. | V13: 9 | AD13: twilight, night | AE13: Investig. | AF13: 20 | AG13: =CONCATENATE("|",AE14,"|","cfs","|",5,"|","3+2b|") -> |Larceny|cfs|5|3+2b|
A14: Fiery Arrow Attack | B14: 1 | T14: zenith | U14: Survival | V14: 10 | AD14: night, eclipse | AE14: Larceny | AF14: 22 | AG14: =CONCATENATE("|",AE15,"|","cfs","|",5,"|","3+2b|") -> |Linguistics|cfs|5|3+2b|
A15: Force Without Fire | B15: 1 | T15: zenith, twilight | U15: Integrity | V15: 11 | AD15: twilight, eclipse | AE15: Linguistics | AF15: 18 | AG15: =CONCATENATE("|",AE16,"|","cfs","|",5,"|","3+2b|") -> |Lore|cfs|5|3+2b|
A16: Athletics | B16: 12 | T16: zenith, twilight | U16: Lore | V16: 12 | AD16: zenith, twilight | AE16: Lore | AF16: 12 | AG16: =CONCATENATE("|",AE17,"|","cfs","|",5,"|","3+2b|") -> |Martial Arts|cfs|5|3+2b|
A17: 1 | B17: 1 | T17: zenith, night | U17: Athletics | V17: 13 | AD17: - | AE17: Martial Arts | AF17: 26 | AG17: =CONCATENATE("|",AE18,"|","cfs","|",5,"|","3+2b|") -> |Medicine|cfs|5|3+2b|
A18: Graceful Crane Stance | B18: 1 | T18: zenith, eclipse | U18: Presence | V18: 14 | AD18: twilight | AE18: Medicine | AF18: 16 | AG18: =CONCATENATE("|",AE19,"|","cfs","|",5,"|","3+2b|") -> |Melee|cfs|5|3+2b|
A19: 2 | B19: 2 | T19: twilight | U19: Craft | V19: 15 | AD19: dawn | AE19: Melee | AF19: 3 | AG19: =CONCATENATE("|",AE20,"|","cfs","|",5,"|","3+2b|") -> |Occult|cfs|5|3+2b|
A20: Foe-Vaulting Method | B20: 1 | T20: twilight | U20: Medicine | V20: 16 | AD20: twilight, eclipse | AE20: Occult | AF20: 19 | AG20: =CONCATENATE("|",AE21,"|","cfs","|",5,"|","3+2b|") -> |Perform.|cfs|5|3+2b|
A21: Monkey Leap Technique | B21: 1 | T21: twilight, eclipse | U21: Bureaucr. | V21: 17 | AD21: zenith | AE21: Perform. | AF21: 9 | AG21: =CONCATENATE("|",AE22,"|","cfs","|",5,"|","3+2b|") -> |Presence|cfs|5|3+2b|
A22: 3 | B22: 5 | T22: twilight, eclipse | U22: Linguistics | V22: 18 | AD22: zenith, eclipse | AE22: Presence | AF22: 14 | AG22: =CONCATENATE("|",AE23,"|","cfs","|",5,"|","3+2b|") -> |Resistan.|cfs|5|3+2b|
A23: Feather Foot Style | B23: 1 | T23: twilight, eclipse | U23: Occult | V23: 19 | AD23: dawn, zenith | AE23: Resistan. | AF23: 5 | AG23: =CONCATENATE("|",AE24,"|","cfs","|",5,"|","3+2b|") -> |Ride|cfs|5|3+2b|
A24: Increasing Strength Exercise | B24: 1 | T24: twilight, night | U24: Investig. | V24: 20 | AD24: night, eclipse | AE24: Ride | AF24: 23 | AG24: =CONCATENATE("|",AE25,"|","cfs","|",5,"|","3+2b|") -> |Sail|cfs|5|3+2b|
A25: Lightning Speed | B25: 1 | T25: night | U25: Stealth | V25: 21 | AD25: eclipse | AE25: Sail | AF25: 25 | AG25: =CONCATENATE("|",AE26,"|","cfs","|",5,"|","3+2b|") -> |Socialize|cfs|5|3+2b|
A26: Soaring Crane Leap | B26: 1 | T26: night, eclipse | U26: Larceny | V26: 22 | AD26: night, eclipse | AE26: Socialize | AF26: 24 | AG26: =CONCATENATE("|",AE27,"|","cfs","|",5,"|","3+2b|") -> |Stealth|cfs|5|3+2b|
A27: Thunderbolt Attack Prana | B27: 1 | T27: night, eclipse | U27: Ride | V27: 23 | AD27: night | AE27: Stealth | AF27: 21 | AG27: =CONCATENATE("|",AE28,"|","cfs","|",5,"|","3+2b|") -> |Survival|cfs|5|3+2b|
A28: 4 | B28: 3 | T28: night, eclipse | U28: Socialize | V28: 24 | AD28: zenith | AE28: Survival | AF28: 10 | AG28: =CONCATENATE("|",AE29,"|","cfs","|",5,"|","3+2b|") -> |Thrown|cfs|5|3+2b|
A29: Spider Foot Style | B29: 1 | T29: eclipse | U29: Sail | V29: 25 | AD29: dawn | AE29: Thrown | AF29: 4 | AG29: =CONCATENATE("|",AE30,"|","cfs","|",5,"|","3+2b|") -> |War|cfs|5|3+2b|
A30: Strength-Hying Heave | B30: 1 | T30: Общий итог | AD30: dawn, zenith | AE30: War | AF30: 6 | AG30: =CONCATENATE("|",AE31,"|","cfs","|",5,"|","3+2b|") -> ||cfs|5|3+2b|
A31: Winning Stride Discipline | B31: 1
A32: 5 | B32: 1
A33: Ten Ox Meditation | B33: 1
A34: Awareness | B34: 11
A35: 2 | B35: 1
A36: Sensory Acuity Prana | B36: 1
A37: 3 | B37: 7
A38: Eyeless Harbinger Awareness | B38: 1
A39: Genius Palate Summation | B39: 1
A40: Keen Hearing and Touch Technique | B40: 1
A41: Keen Sight Technique | B41: 1
...

Sheet Solarlist
A1: Type | B1: Name | C1: Cost | D1: Type | E1: Keywords | F1: Duration | G1: Description | H1: Page # | I1: Ability | J1: Abil. Min | K1: Ess. Min | L1: Aspect Space | M1: Prerequisites | N1: Prereq Spec. | P1: w
A2: Solar | B2: Wise Arrow | C2: 1m | D2: Supplemental | E2: Uniform | F2: Instant | G2: Reduce cover by -1, including no cover. After aiming, can hit around full cover, at only +3 defense. | H2: 255 | I2: Archery | J2: 2 | K2: 1 | L2: dawn
A3: Solar | B3: Trance of Unhesitating Speed | C3: 4m, 1wp | D3: Simple | E3: Decisive-only | F3: Instant | G3: Spread init over many attacks, on single or multiple targets. Each 10 on attack gives +1 base damage. Doesn't need to aim. | H3: 256 | I3: Archery | J3: 3 | K3: 1 | L3: dawn | M3: Wise Arrow
A4: Solar | B4: Phantom Arrow Technique | C4: 1m | D4: Reflexive | E4: None | F4: Instant | G4: Fire without ammo. Imbue ammo with an intimacy. At 3ess, arrows are stuck. | H4: 257 | I4: Archery | J4: 3 | K4: 1 | L4: dawn
A5: Solar | B5: Blood Without Balance | C5: 3m | D5: Reflexive | E5: Decisive-only | F5: Instant | G5: After gaining the benefit of a distract gambit and if your new initiative allows you to act immediately, you may fire up to long range without aiming. If <7 initiative, +ess dice base damage. | H5: 256 | I5: Archery | J5: 4 | K5: 1 | L5: dawn | M5: Sight Without Eyes
A6: Solar | B6: Force Without Fire | C6: 3m | D6: Supplemental | E6: Withering-Only | F6: Instant | G6: If damge is at least as much as the target's stamina, don't gain initiative, but target is knocked down and back 1 range band. Can end a rush. | H6: 256 | I6: Archery | J6: 4 | K6: 1 | L6: dawn | M6: Sight Without Eyes
A7: Solar | B7: Fiery Arrow Attack | C7: 2m | D7: Supplemental | E7: Decisive-only | F7: Instant | G7: Set ammo on fire, gives +1 succ to damage. If it does at least 3HL, target is on fire. | H7: 257 | I7: Archery | J7: 4 | K7: 1 | L7: dawn | M7: Phantom Arrow Technique
A8: Solar | B8: Hanging Judgment Arc | C8: 6m | D8: Reflexive | E8: Decisive-only | F8: Instant | H8: MotSE 5 | I8: Archery | J8: 4 | K8: 2 | L8: dawn | M8: Fiery Arrow Attack
A9: Solar | B9: There Is No Wind | C9: 3m | D9: Reflexive | E9: Dual | F9: Instant | G9: Ignore non-visual penalties. Wither accuracy is set to short range. With Awarenesss, can attack from extreme long range. | H9: 257 | I9: Archery | J9: 5 | K9: 2 | L9: dawn | M9: Sight Without Eyes
A10: Solar | B10: Accuracy Without Distance | C10: 1m, 1wp | D10: Reflexive | E10: Decisive-only | F10: Instant | G10: Aim instantly, the +3 bonus is converted into non-charm succ. | H10: 257 | I10: Archery | J10: 5 | K10: 2 | L10: dawn | M10: Force Without Fire
A11: Solar | B11: Arrow Storm Technique | C11: 5m, 1wp | D11: Simple | E11: Decisive-only | F11: Instant | G11: Hit 3x ess targets within medium range of target. | H11: 257 | I11: Archery | J11: 5 | K11: 2 | L11: dawn | M11: Trance of Unhesitating Speed
A12: Solar | B12: Flashing Vengeance Draw | C12: 3m | D12: Supplemental | E12: None | F12: Instant | G12: Add ess succ to Join Battle, if attacking before target, it's unblockable. | H12: 258 | I12: Archery | J12: 5 | K12: 2 | L12: dawn | M12: Trance of Unhesitating Speed
A13: Solar | B13: Hunter's Swift Answer | C13: 5m, 1wp | D13: Reflexive | E13: Uniform | F13: Instant | G13: Extra short or close ranged attack if win a disengage. | H13: 258 | I13: Archery | J13: 5 | K13: 2 | L13: dawn | M13: Flashing Vengeance Draw
A14: Solar | B14: Dazzling Flare Attack | C14: 3m | D14: Reflexive | E14: Decisive-only | F14: Instant | G14: Strengthens ammo from FAA. Creates a bright flare, disrupting shadow cover. | H14: 258 | I14: Archery | J14: 5 | K14: 2 | L14: dawn | M14: Fiery Arrow Attack
A15: Solar | B15: Seven Omens Shot | C15: 3m, 1wp | D15: Simple | E15: Decisive-only | F15: Instant | G15: Aim for 3 rounds to convert the +3 into non-charm succ and extra succ add to raw damage. AWD shortens it by 1 round. Killing gives 1 WP. | H15: 258 | I15: Archery | J15: 5 | K15: 3 | L15: dawn | M15: Accuracy Without Distance
A16: Solar | B16: Revolving Bow Discipline | C16: 6m, 1wp | D16: Simple | E16: Perilous, Withering-Only | F16: Instant | G16: Keeping hitting the same target within short range, until you miss or they crash. | H16: 259 | I16: Archery | J16: 5 | K16: 3 | L16: dawn | M16: Arrow Storm Technique
A17: Solar | B17: Finishing Snipe | C17: 7m | D17: Reflexive | E17: Decisive-only | F17: Instant | G17: Free attack on someone within range if they crash. | H17: 259 | I17: Archery | J17: 5 | K17: 3 | L17: dawn | M17: Hunter's Swift Answer
A18: Solar | B18: Rain of Feathered Death | C18: 3m/copy, 1wp | D18: Simple | E18: Decisive-only | F18: Instant | G18: Make (Dex) hits against a target. | H18: 259 | I18: Archery | J18: 5 | K18: 3 | L18: dawn | M18: Phantom Arrow Technique
A19: Solar | B19: Shadow-Seeking Arrow | C19: 3m, 2i | D19: Reflexive | E19: Uniform | F19: Instant | G19: Free attack when spotting someone, without needing to aim. | H19: 259 | I19: Archery | J19: 5 | K19: 3 | L19: dawn | M19: Dazzling Flare Attack
A20: Solar | B20: Searing Sunfire Interdiction | C20: 4m, 1i, 1wp | D20: Simple | E20: Decisive-only | F20: Instant | G20: Diff 3 gambit without needing to aim. Forces target to delay their turn. Rebuy for lots of extra stuff. | H20: 259 | I20: Archery | J20: 5 | K20: 3 | L20: dawn | M20: Dazzling Flare Attack
... A23: Solar | B23: Heart-Eating Incineration | C23: 3m, 3a | D23: Reflexive | E23: Decisive-only | F23: Instant | G23: When using SS and anima is at bonfire, fires anima to add initiative to SS's raw damage. | H23: 260 | I23: Archery | J23: 5 | K23: 3 | L23: dawn | M23: Solar Spike
A24: Solar | B24: Nova Arrow Attack | C24: 6m, 1wp | D24: Simple | E24: Decisive-only | F24: Instant | H24: MotSE 6 | I24: Archery | J24: 5 | K24: 3 | L24: dawn | M24: Dazzling Flare Attack
A25: Solar | B25: Searing Sunfire Interdiction x3 | C25: 4m, 1i, 1wp | D25: Simple | E25: Decisive-only | F25: Instant | G25: Resets attack if you drop target from high Init to lower | H25: 259 | I25: Archery | J25: 5 | K25: 4 | L25: dawn | M25: Searing Sunfire Interdiction x2
A26: Solar | B26: Dust and Ash Sleight | C26: 3m | D26: Reflexive | E26: Decisive-only | F26: Instant | G26: Shortens the aim action of SOS by 1 round, giving up the non charm successes. Rebuy to gain the succ again. | H26: 260 | I26: Archery | J26: 5 | K26: 4 | L26: dawn | M26: Seven Omens Shot
A27: Solar | B27: Heavens Crash Down | C27: 6m, 2i, 1wp | D27: Reflexive | E27: Clash, Perilous, Withering-Only | F27: Instant | G27: If in -4 HLs, may clash within short range. Gains ess succ and damage roll uses double 9s. Rebuy to use while crashed. | H27: 260 | I27: Archery | J27: 5 | K27: 4 | L27: dawn | M27: Revolving Bow Discipline
A28: Solar | B28: Hell-Heeling Arrow | C28: 13m, 1wp | D28: Simple | E28: Decisive-only | F28: Instant | H28: MotSE 6 | I28: Archery | J28: 5 | K28: 4 | L28: dawn | M28: Nova Arrow Attack, Searing Sunfire Interdiction
A29: Solar | B29: Accuracy Without Distance x2 | C29: 1m, 1wp | D29: Reflexive | E29: Dual | F29: Instant | G29: Can use with withering on a crashed target. Roll damage even if no succ. | H29: 257 | I29: Archery | J29: 5 | K29: 5 | L29: dawn | M29: Accuracy Without Distance
A30: Solar | B30: Searing Sunfire Interdiction x4 | C30: 4m, 1i, 1wp | D30: Simple | E30: Decisive-only | F30: Instant | G30: Can use twice consecutively on the same target, no wp cost on 2nd shot. | H30: 259 | I30: Archery | J30: 5 | K30: 5 | L30: dawn | M30: Searing Sunfire Interdiction x3
A31: Solar | B31: Dust and Ash Sleight x2 | C31: 3m | D31: Reflexive | E31: Decisive-only | F31: Instant | G31: Adds back loss succ to the attack. | H31: 260 | I31: Archery | J31: 5 | K31: 5 | L31: dawn | M31: Dust and Ash Sleight
A32: Solar | B32: Heavens Crash Down x2 | C32: 6m, 2i, 1wp | D32: Reflexive | E32: Clash, Withering-Only | F32: Instant | G32: Can spend 2i cost even when crashed going into further negatives. | H32: 260 | I32: Archery | J32: 5 | K32: 5 | L32: dawn | M32: Heavens Crash Down
A33: Solar | B33: Whispered Prayer of Judgment | C33: 1m | D33: Supplemental | E33: Uniform | F33: Instant | G33: After aiming, add ess damage to the attack. | H33: 261 | I33: Archery | J33: 5 | K33: 5 | L33: dawn | M33: Streaming Arrow Stance
A34: Solar | B34: Solar Judgment Flare | C34: 3m, 1wp and 1m/die | D34: Simple | E34: Decisive-only | F34: Instant | H34: MotSE 6 | I34: Archery | J34: 5 | K34: 5 | L34: dawn | M34: Heart-Eating Incineration, Nova Arrow Attack
A35: Solar | B35: Searing Sunfire Interdiction x5 | C35: 4m, 1i, 1wp | D35: Simple | E35: Decisive-only | F35: Instant | G35: Can use repeatedly on same target if you keep hitting. Ends with miss or when target loses a turn. Gain 1wp if target loses turn. | H35: 259 | I35: Archery | J35: 5 | K35: 6 | L35: dawn | M35: Searing Sunfire Interdiction x4
A36: Solar | B36: Searing Sunfire Interdiction x6 | C36: 4m, 1i, 1wp | D36: Simple | E36: Decisive-only | F36: Instant | G36: Can target new opponent if you drop someone to tick 0 or lower. | H36: 259 | I36: Archery | J36: 5 | K36: 6 | L36: dawn | M36: Searing Sunfire Interdiction x5
A37: Solar | B37: Sight Without Eyes | C37: 1m | D37: Reflexive | E37: None | F37: One Tick | G37: Can fire without penalty due to visual conditions. at 3ess can see through cover. | H37: 255 | I37: Archery | J37: 3 | K37: 1 | L37: dawn | M37: Wise Arrow
A38: Solar | B38: Immaculate Golden Bow | C38: 5m, 1wp | D38: Simple | E38: None | F38: Scene | G38: Create a glowing powerbow from essence. 4m to make heavy cover. Rebuy for evocations. | H38: 258 | I38: Archery | J38: 4 | K38: 2 | L38: dawn | M38: Phantom Arrow Technique
A39: Solar | B39: Streaming Arrow Stance | C39: 6m | D39: Simple | E39: None | F39: Scene | G39: Can shoot a crashed target at medium or long range without aiming. | H39: 260 | I39: Archery | J39: 5 | K39: 4 | L39: dawn | M39: Finishing Snipe
A40: Solar | B40: Dedicated Unerring Ear | C40: 3m/exchange | D40: Reflexive | E40: None | F40: Indefinite | G40: Hear anyone on your plane talking to you. One-way only. | H40: 273 | I40: Awareness | J40: 5 | K40: 4 | L40: dawn, night | M40: Unsurpassed Hearing and Touch Discipline
A41: Solar | B41: Surprise Anticipation Method | C41: - | D41: Reflexive | E41: None | F41: Instant | G41: Every 9 gives 1m, 10 gives 2m for Awarenesss charms, can lower cost retroactively. Also can use Awarenesss charms in sleep. | H41: 267 | I41: Awareness | J41: 3 | K41: 1 | L41: dawn, night | M41: Sensory Acuity Prana
A42: Solar | B42: Genius Palate Summation | C42: 2m | D42: Simple | E42: None | F42: Instant | G42: Autowin read intentions on chef when they made your food. | H42: 269 | I42: Awareness | J42: 3 | K42: 1 | L42: dawn, night | M42: Keen Taste and Smell Technique
...

Sheet Siderial
A1: Type | B1: Name | C1: Выбор | D1: Фильтрация | E1: Комменты | F1: Дом | G1: Дева | H1: Созвездие | I1: Cost | J1: Type | K1: Keywords | L1: Duration | M1: Description | N1: Page # | O1: Ability | P1: Abil. Min | Q1: Ess. Min | R1: Aspect Space | S1: Prerequisites | T1: Prereq Spec.
A2: Sidereal | B2: Icy Hand | C2: зеленый | D2: возможно | E2: это про Бюро | F2: =VLOOKUP(O2,pearl!$B:$E,4,0) -> ♄ | G2: =VLOOKUP(IF(F2="Дом",H2,F2),pearl!$D$28:$F$32,3,0) -> Сатурн | H2: =VLOOKUP(O2,pearl!$B:$E,3,0) -> ♄Телега с сеном | I2: 1m, 1wp | J2: Simple | K2: Psyche | L2: Indefinite | M2: "нормально делай нормально будет" | N2: Sid 300 | O2: Bureaucracy | P2: 3 | Q2: 1 | R2: 0 | S2: None
A3: Sidereal | B3: Feathered Cloak Trick | C3: зеленый | D3: возможно | E3: цикл на врановых | F3: =VLOOKUP(O3,pearl!$B:$E,4,0) -> ♄ | G3: =VLOOKUP(IF(F3="Дом",H3,F3),pearl!$D$28:$F$32,3,0) -> Сатурн | H3: =VLOOKUP(O3,pearl!$B:$E,3,0) -> ♄Ворон | I3: 4m | J3: Simple | K3: Mute | L3: Indefinite | N3: Sid 296 | O3: Awareness | P3: 4 | Q3: 1 | R3: 0 | S3: None
A4: Sidereal | B4: Reading Dead Eyes | C4: зеленый | D4: возможно | E4: цикл на поствидение | F4: =VLOOKUP(O4,pearl!$B:$E,4,0) -> ♄ | G4: =VLOOKUP(IF(F4="Дом",H4,F4),pearl!$D$28:$F$32,3,0) -> Сатурн | H4: =VLOOKUP(O4,pearl!$B:$E,3,0) -> ♄Ворон | I4: 5m, 1wp | J4: Simple | K4: Mute | L4: Instant | N4: Sid 298 | O4: Awareness | P4: 4 | Q4: 2 | R4: 0 | S4: Feathered Cloak Trick
A5: Sidereal | B5: Expected Pain | C5: зеленый | D5: возможно | E5: цикл на предвидение жопы | F5: =VLOOKUP(O5,pearl!$B:$E,4,0) -> ♄ | G5: =VLOOKUP(IF(F5="Дом",H5,F5),pearl!$D$28:$F$32,3,0) -> Сатурн | H5: =VLOOKUP(O5,pearl!$B:$E,3,0) -> ♄Ворон | I5: - (5m) | J5: Permanent | K5: Divination, Mute, Uniform | L5: Permanent | N5: Sid 295 | O5: Awareness | P5: 3 | Q5: 1 | R5: 0 | S5: Prior Warning
A6: Sidereal | B6: Heavenly Sentinel Eye | C6: зеленый | D6: возможно | E6: цикл на предвидение жопы | F6: =VLOOKUP(O6,pearl!$B:$E,4,0) -> ♄ | G6: =VLOOKUP(IF(F6="Дом",H6,F6),pearl!$D$28:$F$32,3,0) -> Сатурн | H6: =VLOOKUP(O6,pearl!$B:$E,3,0) -> ♄Ворон | I6: 4m | J6: Reflexive | K6: None | L6: Instant | N6: Sid 295 | O6: Awareness | P6: 3 | Q6: 1 | R6: 0 | S6: Prior Warning
A7: Sidereal | B7: Prior Warning | C7: зеленый | D7: возможно | E7: цикл на предвидение жопы | F7: =VLOOKUP(O7,pearl!$B:$E,4,0) -> ♄ | G7: =VLOOKUP(IF(F7="Дом",H7,F7),pearl!$D$28:$F$32,3,0) -> Сатурн | H7: =VLOOKUP(O7,pearl!$B:$E,3,0) -> ♄Ворон | I7: - | J7: Permanent | K7: Divination | L7: Permanent | N7: Sid 294 | O7: Awareness | P7: 1 | Q7: 1 | R7: 0 | S7: None
A8: Sidereal | B8: Someone’s Son Style | C8: синий | D8: возможно | E8: в сияющей судьбе | F8: =VLOOKUP(O8,pearl!$B:$E,4,0) -> Дом | G8: =VLOOKUP(IF(F8="Дом",H8,F8),pearl!$D$28:$F$32,3,0) -> Марс | H8: =VLOOKUP(O8,pearl!$B:$E,3,0) -> ♂ | I8: - | J8: Permanent | K8: None | L8: Permanent | N8: Sid 224 | O8: Battles | P8: 2 | Q8: 1 | R8: 0 | S8: Any three Battles Charms
A9: Sidereal | B9: Favorable Inflection Procedure | C9: синий | D9: возможно | E9: Социалка | F9: =VLOOKUP(O9,pearl!$B:$E,4,0) -> ♄ | G9: =VLOOKUP(IF(F9="Дом",H9,F9),pearl!$D$28:$F$32,3,0) -> Сатурн | H9: =VLOOKUP(O9,pearl!$B:$E,3,0) -> ♄Меч | I9: 5m | J9: Reflexive | K9: Mute | L9: Instant | M9: постоянная планка для Резолва | N9: Sid 307 | O9: Integrity | P9: 2 | Q9: 1 | R9: 0 | S9: None
A10: Sidereal | B10: Shadow-Piercing Needle | C10: синий | D10: возможно | E10: как она дерется | F10: =VLOOKUP(O10,pearl!$B:$E,4,0) -> ☿ | G10: =VLOOKUP(IF(F10="Дом",H10,F10),pearl!$D$28:$F$32,3,0) -> Меркурий | H10: =VLOOKUP(O10,pearl!$B:$E,3,0) -> ☿Чайка | I10: 3m | J10: Supplemental | K10: Dual, Versatile | L10: Instant | N10: Sid 183 | O10: Thrown | P10: 3 | Q10: 1 | R10: 0 | S10: None
A11: Sidereal | B11: In Destiny’s Service | C11: синий | D11: возможно | E11: это про Бюро | F11: =VLOOKUP(O11,pearl!$B:$E,4,0) -> ♄ | G11: =VLOOKUP(IF(F11="Дом",H11,F11),pearl!$D$28:$F$32,3,0) -> Сатурн | H11: =VLOOKUP(O11,pearl!$B:$E,3,0) -> ♄Меч | I11: 5m | J11: Reflexive | K11: None | L11: Instant | M11: призывать свою компетенцию для Резолва | N11: Sid 308 | O11: Integrity | P11: 5 | Q11: 3 | R11: 0 | S11: Minimum Legal Defense Competence
A12: Sidereal | B12: Supernal Awareness (x2) | C12: синий | D12: возможно | E12: усиление по расстоянию | F12: =VLOOKUP(O12,pearl!$B:$E,4,0) -> ♄ | G12: =VLOOKUP(IF(F12="Дом",H12,F12),pearl!$D$28:$F$32,3,0) -> Сатурн | H12: =VLOOKUP(O12,pearl!$B:$E,3,0) -> ♄Ворон | I12: 5m (5m, 1wp) | J12: Simple | K12: Stackable | L12: One scene | N12: Sid 296 | O12: Awareness | P12: 5 | Q12: 3 | R12: 0 | S12: Supernal Awareness
A13: Sidereal | B13: Dark-Winged Watcher | C13: синий | D13: возможно | E13: цикл на врановых | F13: =VLOOKUP(O13,pearl!$B:$E,4,0) -> ♄ | G13: =VLOOKUP(IF(F13="Дом",H13,F13),pearl!$D$28:$F$32,3,0) -> Сатурн | H13: =VLOOKUP(O13,pearl!$B:$E,3,0) -> ♄Ворон | I13: 5m, 1wp | J13: Simple | K13: None | L13: (Essence + Perception) days | N13: Sid 298 | O13: Awareness | P13: 5 | Q13: 2 | R13: 0 | S13: Feathered Cloak Trick, Supernal Awareness
A14: Sidereal | B14: Old Sorrows Reminiscence | C14: синий | D14: возможно | E14: цикл на поствидение | F14: =VLOOKUP(O14,pearl!$B:$E,4,0) -> ♄ | G14: =VLOOKUP(IF(F14="Дом",H14,F14),pearl!$D$28:$F$32,3,0) -> Сатурн | H14: =VLOOKUP(O14,pearl!$B:$E,3,0) -> ♄Ворон | I14: 7m, 1wp | J14: Simple | K14: Divination, Mute | L14: Instant | N14: Sid 298 | O14: Awareness | P14: 5 | Q14: 3 | R14: 0 | S14: Prior Warning, Reading Dead Eyes
A15: Sidereal | B15: Promise of Tomorrow | C15: синий | D15: вполне | E15: надежда | F15: =VLOOKUP(O15,pearl!$B:$E,4,0) -> ♄ | G15: =VLOOKUP(IF(F15="Дом",H15,F15),pearl!$D$28:$F$32,3,0) -> Сатурн | H15: =VLOOKUP(O15,pearl!$B:$E,3,0) -> ♄Меч | I15: 2m | J15: Reflexive | K15: None | L15: Indefinite | M15: работа с связями надежды | N15: Sid 306 | O15: Integrity | P15: 4 | Q15: 1 | R15: 0 | S15: Until Hope's End
A16: Sidereal | B16: Honest Face Spirit | C16: зеленый | D16: вполне | E16: в сияющей судьбе | F16: =VLOOKUP(O16,pearl!$B:$E,4,0) -> Дом | G16: =VLOOKUP(IF(F16="Дом",H16,F16),pearl!$D$28:$F$32,3,0) -> Меркурий | H16: =VLOOKUP(O16,pearl!$B:$E,3,0) -> ☿ | I16: 3m | J16: Reflexive | K16: Mute | L16: One scene | N16: Sid 158 | O16: Journeys | P16: 2 | Q16: 1 | R16: 0 | S16: Any Journeys Charm
A17: Sidereal | B17: Until Hope’s End | C17: синий | D17: вполне | E17: надежда | F17: =VLOOKUP(O17,pearl!$B:$E,4,0) -> ♄ | G17: =VLOOKUP(IF(F17="Дом",H17,F17),pearl!$D$28:$F$32,3,0) -> Сатурн | H17: =VLOOKUP(O17,pearl!$B:$E,3,0) -> ♄Меч | I17: - | J17: Permanent | K17: None | L17: Permanent | M17: работа с связями надежды | N17: Sid 305 | O17: Integrity | P17: 1 | Q17: 1 | R17: 0 | S17: None
A18: Sidereal | B18: Returning Swallow Flight | C18: зеленый | D18: вполне | E18: притягивать вещи | F18: =VLOOKUP(O18,pearl!$B:$E,4,0) -> ☿ | G18: =VLOOKUP(IF(F18="Дом",H18,F18),pearl!$D$28:$F$32,3,0) -> Меркурий | H18: =VLOOKUP(O18,pearl!$B:$E,3,0) -> ☿Чайка | I18: 5m | J18: Supplemental | K18: Decisive-only, Versatile | L18: Instant | N18: Sid 183 | O18: Thrown | P18: 3 | Q18: 1 | R18: 0 | S18: None
A19: Sidereal | B19: Shrike-Roosting Gesture | C19: зеленый | D19: вполне | E19: притягивать вещи | F19: =VLOOKUP(O19,pearl!$B:$E,4,0) -> ☿ | G19: =VLOOKUP(IF(F19="Дом",H19,F19),pearl!$D$28:$F$32,3,0) -> Меркурий | H19: =VLOOKUP(O19,pearl!$B:$E,3,0) -> ☿Чайка | I19: 3m (1m) | J19: Reflexive | K19: None | L19: Instant | N19: Sid 183 | O19: Thrown | P19: 3 | Q19: 1 | R19: 0 | S19: Returning Swallow Flight
A20: Sidereal | B20: Good Worker Spirit | C20: зеленый | D20: вполне | E20: это работа в Бюро | F20: =VLOOKUP(O20,pearl!$B:$E,4,0) -> Дом | G20: =VLOOKUP(IF(F20="Дом",H20,F20),pearl!$D$28:$F$32,3,0) -> Меркурий | H20: =VLOOKUP(O20,pearl!$B:$E,3,0) -> ☿ | I20: 5m | J20: Supplemental | K20: Mute | L20: Instant | N20: Sid 158 | O20: Journeys | P20: 3 | Q20: 1 | R20: 0 | S20: Honest Face Spirit
A21: Sidereal | B21: Forgotten Earth | C21: зеленый | D21: вполне | E21: прыгать вместе с Бангом | F21: =VLOOKUP(O21,pearl!$B:$E,4,0) -> ♄ | G21: =VLOOKUP(IF(F21="Дом",H21,F21),pearl!$D$28:$F$32,3,0) -> Сатурн | H21: =VLOOKUP(O21,pearl!$B:$E,3,0) -> ♄Восходящий Дым | I21: 3m | J21: Reflexive | K21: Mute | L21: Instant | M21: как соларская атлетика | N21: Sid 290 | O21: Athletics | P21: 2 | Q21: 1 | R21: 0 | S21: None
A22: Sidereal | B22: Terminal Sanction | C22: зеленый | D22: вполне | E22: работа с духами | F22: =VLOOKUP(O22,pearl!$B:$E,4,0) -> ♄ | G22: =VLOOKUP(IF(F22="Дом",H22,F22),pearl!$D$28:$F$32,3,0) -> Сатурн | H22: =VLOOKUP(O22,pearl!$B:$E,3,0) -> ♄Телега с сеном | I22: 5m | J22: Simple | K22: None | L22: Instant | M22: принуждение материализоваться | N22: Sid 300 | O22: Bureaucracy | P22: 2 | Q22: 1 | R22: 0 | S22: None
A23: Sidereal | B23: Superior-Entreating Memorial Style | C23: зеленый | D23: вполне | E23: секретные письма в Бюро | F23: =VLOOKUP(O23,pearl!$B:$E,4,0) -> Дом | G23: =VLOOKUP(IF(F23="Дом",H23,F23),pearl!$D$28:$F$32,3,0) -> Сатурн | H23: =VLOOKUP(O23,pearl!$B:$E,3,0) -> ♄ | I23: 1m | J23: Simple | K23: None | L23: Instant | M23: исчезающие письма | N23: Sid 288 | O23: Endings | P23: 1 | Q23: 1 | R23: 0 | S23: Any Endings Charm
A24: Sidereal | B24: Inevitable Pursuit | C24: зеленый | D24: вполне | E24: цикл на слежку | F24: =VLOOKUP(O24,pearl!$B:$E,4,0) -> ♄ | G24: =VLOOKUP(IF(F24="Дом",H24,F24),pearl!$D$28:$F$32,3,0) -> Сатурн | H24: =VLOOKUP(O24,pearl!$B:$E,3,0) -> ♄Ворон | I24: 4m | J24: Simple | K24: None | L24: Instant | N24: Sid 296 | O24: Awareness | P24: 3 | Q24: 1 | R24: 0 | S24: None
A25: Sidereal | B25: Supernal Awareness | C25: зеленый | D25: вполне | E25: цикл на слежку | F25: =VLOOKUP(O25,pearl!$B:$E,4,0) -> ♄ | G25: =VLOOKUP(IF(F25="Дом",H25,F25),pearl!$D$28:$F$32,3,0) -> Сатурн | H25: =VLOOKUP(O25,pearl!$B:$E,3,0) -> ♄Ворон | I25: 5m | J25: Simple | K25: Stackable | L25: One scene | N25: Sid 296 | O25: Awareness | P25: 4 | Q25: 1 | R25: 0 | S25: Inevitable Pursuit
A26: Sidereal | B26: Magpie’s Favorite Bauble | C26: синий | D26: вполне | E26: притягивать вещи | F26: =VLOOKUP(O26,pearl!$B:$E,4,0) -> ☿ | G26: =VLOOKUP(IF(F26="Дом",H26,F26),pearl!$D$28:$F$32,3,0) -> Меркурий | H26: =VLOOKUP(O26,pearl!$B:$E,3,0) -> ☿Чайка | I26: - (+3m) | J26: Permanent | K26: None | L26: Permanent | N26: Sid 186 | O26: Thrown | P26: 5 | Q26: 2 | R26: 0 | S26: Shrike-Roosting Gesture
A27: Sidereal | B27: Water and Fire Treaty | C27: синий | D27: возможно | E27: для путешествий | F27: =VLOOKUP(O27,pearl!$B:$E,4,0) -> ♂ | G27: =VLOOKUP(IF(F27="Дом",H27,F27),pearl!$D$28:$F$32,3,0) -> Марс | H27: =VLOOKUP(O27,pearl!$B:$E,3,0) -> Щит♂ | I27: 1m, 1ahl | J27: Simple | K27: Decisive-only, Stackable | L27: One story | N27: Sid 244 | O27: Presence | P27: 2 | Q27: 1 | R27: 0 | S27: None
A28: Sidereal | B28: Impose Nature | C28: зеленый | D28: вполне | E28: наделить своей чертой | F28: =VLOOKUP(O28,pearl!$B:$E,4,0) -> ♂ | G28: =VLOOKUP(IF(F28="Дом",H28,F28),pearl!$D$28:$F$32,3,0) -> Марс | H28: =VLOOKUP(O28,pearl!$B:$E,3,0) -> Щит♂ | I28: 7m | J28: Simple | K28: Mute, Psyche | L28: Instant | N28: Sid 243 | O28: Presence | P28: 2 | Q28: 1 | R28: 0 | S28: None
A29: Sidereal | B29: Wise Choice | C29: синий | D29: вполне | E29: ясновидение Гранат | F29: =VLOOKUP(O29,pearl!$B:$E,4,0) -> ♄ | G29: =VLOOKUP(IF(F29="Дом",H29,F29),pearl!$D$28:$F$32,3,0) -> Сатурн | H29: =VLOOKUP(O29,pearl!$B:$E,3,0) -> ♄Ворон | I29: 6m | J29: Simple | K29: Divination | L29: Instant | N29: Sid 296 | O29: Awareness | P29: 1 | Q29: 1 | R29: 0 | S29: None
A30: Sidereal | B30: Insatiable Weapon Wanderlust | C30: зеленый | D30: вряд ли | E30: как она дерется | F30: =VLOOKUP(O30,pearl!$B:$E,4,0) -> ☿ | G30: =VLOOKUP(IF(F30="Дом",H30,F30),pearl!$D$28:$F$32,3,0) -> Меркурий | H30: =VLOOKUP(O30,pearl!$B:$E,3,0) -> ☿Чайка | I30: 2m | J30: Supplemental | K30: Uniform, Versatile | L30: Instant | N30: Sid 183 | O30: Thrown | P30: 3 | Q30: 1 | R30: 0 | S30: None
A31: Sidereal | B31: Willful Weapon Method | C31: зеленый | D31: вряд ли | E31: как она дерется | F31: =VLOOKUP(O31,pearl!$B:$E,4,0) -> ☿ | G31: =VLOOKUP(IF(F31="Дом",H31,F31),pearl!$D$28:$F$32,3,0) -> Меркурий | H31: =VLOOKUP(O31,pearl!$B:$E,3,0) -> ☿Чайка | I31: 2m, 1wp | J31: Simple | K31: Decisive-only | L31: Instant | N31: Sid 184 | O31: Thrown | P31: 3 | Q31: 1 | R31: 0 | S31: None
A32: Sidereal | B32: Borrowed Coffin Ploy | C32: зеленый | D32: вряд ли | E32: Социалка | F32: =VLOOKUP(O32,pearl!$B:$E,4,0) -> Дом | G32: =VLOOKUP(IF(F32="Дом",H32,F32),pearl!$D$28:$F$32,3,0) -> Сатурн | H32: =VLOOKUP(O32,pearl!$B:$E,3,0) -> ♄ | I32: 3m | J32: Simple | K32: Mute | L32: Permanent | M32: "да -не- умер в конце Драйва!" | N32: Sid 288 | O32: Endings | P32: 3 | Q32: 1 | R32: 0 | S32: Any three Endings Charms
A33: Sidereal | B33: Holistic Arsenal Methodology | C33: синий | D33: вряд ли | E33: как она дерется | F33: =VLOOKUP(O33,pearl!$B:$E,4,0) -> Дом | G33: =VLOOKUP(IF(F33="Дом",H33,F33),pearl!$D$28:$F$32,3,0) -> Марс | H33: =VLOOKUP(O33,pearl!$B:$E,3,0) -> ♂ | I33: - (2m) | J33: Permanent | K33: None | L33: Permanent | M33: оружие с тегом МА можно использовать другими навыками | N33: Sid 223 | O33: Battles | P33: 1 | Q33: 1 | R33: 0 | S33: None
A34: Sidereal | B34: Sword-Tongue Intensity | C34: синий | D34: вряд ли | E34: как она дерется | F34: =VLOOKUP(O34,pearl!$B:$E,4,0) -> ♂ | G34: =VLOOKUP(IF(F34="Дом",H34,F34),pearl!$D$28:$F$32,3,0) -> Марс | H34: =VLOOKUP(O34,pearl!$B:$E,3,0) -> Щит♂ | I34: 3m | J34: Reflexive | K34: None | L34: Instant | M34: заговор зубов в бою | N34: Sid 244 | O34: Presence | P34: 4 | Q34: 1 | R34: 0 | S34: None
A35: Sidereal | B35: Ascending Serenity Horoscope | C35: зеленый | D35: проблемы с гороскопами | F35: =VLOOKUP(O35,pearl!$B:$E,4,0) -> Дом | G35: =VLOOKUP(IF(F35="Дом",H35,F35),pearl!$D$28:$F$32,3,0) -> Венера | H35: =VLOOKUP(O35,pearl!$B:$E,3,0) -> ♀ | I35: 1m or 3m, 1wp | J35: Simple | K35: Mute, Shaping (Fate), Stackable | L35: One story | M35: благословение или проклятие | N35: Sid 189 | O35: Serenities | P35: 3 | Q35: 1 | R35: 0 | S35: Any three Serenity Charms
A36: Sidereal | B36: Descending Serenity Horoscope | C36: зеленый | D36: проблемы с гороскопами | F36: =VLOOKUP(O36,pearl!$B:$E,4,0) -> Дом | G36: =VLOOKUP(IF(F36="Дом",H36,F36),pearl!$D$28:$F$32,3,0) -> Венера | H36: =VLOOKUP(O36,pearl!$B:$E,3,0) -> ♀ | I36: 1 or 3m, 1wp | J36: Simple | K36: Mute, Shaping (Fate), Stackable | L36: One story | M36: благословение или проклятие | N36: Sid 189 | O36: Serenities | P36: 3 | Q36: 1 | R36: 0 | S36: Any three Serenity Charms
A37: Sidereal | B37: Ascending Endings Horoscope | C37: зеленый | D37: проблемы с гороскопами | E37: ради всей Айни? | F37: =VLOOKUP(O37,pearl!$B:$E,4,0) -> Дом | G37: =VLOOKUP(IF(F37="Дом",H37,F37),pearl!$D$28:$F$32,3,0) -> Сатурн | H37: =VLOOKUP(O37,pearl!$B:$E,3,0) -> ♄ | I37: 1m or 3m, 1wp | J37: Simple | K37: Mute, Shaping (Fate), Stackable, Uniform | L37: One story | M37: благословение или проклятие | N37: Sid 287 | O37: Endings | P37: 3 | Q37: 1 | R37: 0 | S37: Any three Endings Charms
A38: Sidereal | B38: Ascending Secrets Horoscope | C38: оранж | D38: проблемы с гороскопами | F38: =VLOOKUP(O38,pearl!$B:$E,4,0) -> Дом | G38: =VLOOKUP(IF(F38="Дом",H38,F38),pearl!$D$28:$F$32,3,0) -> Юпитер | H38: =VLOOKUP(O38,pearl!$B:$E,3,0) -> ♃ | I38: 1m or 3m, 1wp | J38: Simple | K38: Mute, Shaping (Fate), Stackable | L38: One story | M38: благословение или проклятие | N38: Sid 255 | O38: Secrets | P38: 3 | Q38: 1 | R38: 0 | S38: Any three Secrets Charms
A39: Sidereal | B39: Ascending Journeys Horoscope | C39: синий | D39: проблемы с гороскопами | F39: =VLOOKUP(O39,pearl!$B:$E,4,0) -> Дом | G39: =VLOOKUP(IF(F39="Дом",H39,F39),pearl!$D$28:$F$32,3,0) -> Меркурий | H39: =VLOOKUP(O39,pearl!$B:$E,3,0) -> ☿ | I39: 1m or 3m, 1wp | J39: Simple | K39: Mute, Shaping (Fate), Stackable | L39: One story | M39: благословение или проклятие | N39: Sid 156 | O39: Journeys | P39: 3 | Q39: 1 | R39: 0 | S39: Any three Journeys Charms
A40: Sidereal | B40: Descending Journeys Horoscope | C40: синий | D40: проблемы с гороскопами | F40: =VLOOKUP(O40,pearl!$B:$E,4,0) -> Дом | G40: =VLOOKUP(IF(F40="Дом",H40,F40),pearl!$D$28:$F$32,3,0) -> Меркурий | H40: =VLOOKUP(O40,pearl!$B:$E,3,0) -> ☿ | I40: 1m or 3m, 1wp | J40: Simple | K40: Mute, Shaping (Fate), Stackable | L40: One story | M40: благословение или проклятие | N40: Sid 158 | O40: Journeys | P40: 3 | Q40: 1 | R40: 0 | S40: Any three Journeys Charms
...

Sheet pearl
A1: C/F | B1: Ability | C1: Навык | D1: Дом/Созвездие | E1: Дом | F1: зел | G1: син | H1: оранж | J1: Type | K1: Sidereal | P1: Type | Q1: Sidereal | X1: Type | Y1: Sidereal
A2: C | B2: Martial Arts | C2: Боевые искусства | D2: - | E2: все | X2: Abil. Min | Y2: 5
B3: Resistance | C3: Сопротивление | D3: ☿Мачта | E3: ☿ | F3: 1 | J3: Количество по полю Выбор | K3: Названия столбцов | P3: Количество по полю Выбор | Q3: Названия столбцов
B4: Ride | C4: Верховая езда | D4: ☿Посланник | E4: ☿ | J4: Названия строк | K4: зеленый | L4: синий | M4: оранж | N4: Общий итог | P4: Названия строк | Q4: зеленый | R4: синий | S4: оранж | T4: Общий итог | X4: Количество по полю Выбор | Y4: Названия столбцов
B5: Sail | C5: Парус. плавание | D5: ☿Капитан | E5: ☿ | J5: ☿ | K5: 5 | L5: 2 | N5: 7 | P5: вполне | Q5: 0.2 | R5: 0.083333333 | S5: 0 | T5: 0.28333333 | X5: Названия строк | Y5: зеленый | Z5: синий | AA5: оранж | AB5: Общий итог
B6: Survival | C6: Выживание | D6: ☿Штурвал | E6: ☿ | J6: Resistance | K6: 1 | N6: 1 | P6: возможно | Q6: 0.1 | R6: 0.18333333 | S6: 0 | T6: 0.28333333 | X6: ☿ | Z6: 1 | AB6: 1
A7: mb | B7: Thrown | C7: Метание | D7: ☿Чайка | E7: ☿ | F7: 2 | G7: 4 | J7: Thrown | K7: 4 | L7: 2 | N7: 6 | P7: проблемы с гороскопами | Q7: 0.05 | R7: 0.033333333 | S7: 0.016666667 | T7: 0.1 | X7: Thrown | Z7: 1 | AB7: 1
A8: C | B8: Craft | C8: Ремесло | D8: ♀Павлин | E8: ♀ | F8: 8 | G8: 2 | H8: 1 | J8: ♀ | K8: 29 | L8: 11 | M8: 2 | N8: 42 | P8: вряд ли | Q8: 0.05 | R8: 0.05 | S8: 0 | T8: 0.1 | X8: ♀ | Y8: 2 | Z8: 5 | AA8: 1 | AB8: 8
A9: C | B9: Dodge | C9: Уклонение | D9: ♀Кувшин | E9: ♀ | F9: 6 | G9: 3 | J9: Craft | K9: 8 | L9: 2 | M9: 1 | N9: 11 | P9: тема не та | Q9: 0 | R9: 0.13333333 | S9: 0.05 | T9: 0.18333333 | X9: Craft | Y9: 1 | Z9: 1 | AB9: 2
A10: C | B10: Linguistics | C10: Лингвистика | D10: ♀Колонна | E10: ♀ | F10: 4 | G10: 2 | J10: Dodge | K10: 6 | L10: 3 | N10: 9 | P10: скучно | Q10: 0.033333333 | R10: 0.016666667 | S10: 0 | T10: 0.05 | X10: Dodge | Y10: 1 | Z10: 2 | AB10: 3
A11: C | B11: Performance | C11: Выступление | D11: ♀Музыкант | E11: ♀ | F11: 4 | G11: 2 | J11: Linguistics | K11: 4 | L11: 2 | N11: 6 | P11: Общий итог | Q11: 0.43333333 | R11: 0.5 | S11: 0.066666667 | T11: 1 | X11: Linguistics | Z11: 1 | AB11: 1
A12: C | B12: Socialize | C12: Социализация | D12: ♀Любовники | E12: ♀ | F12: 7 | G12: 2 | H12: 1 | J12: Performance | K12: 4 | L12: 2 | N12: 6 | X12: Socialize | Z12: 1 | AA12: 1 | AB12: 2
B13: Archery | C13: Стрельба | D13: Колчан♂ | E13: ♂ | J13: Socialize | K13: 7 | L13: 2 | M13: 1 | N13: 10 | X13: ♂ | Z13: 4 | AA13: 1 | AB13: 5
B14: Brawl | C14: Драка | D14: Перчатка♂ | E14: ♂ | J14: ♂ | K14: 4 | L14: 10 | M14: 1 | N14: 15 | X14: Melee | AA14: 1 | AB14: 1
B15: Melee | C15: Ближний бой | D15: Копье♂ | E15: ♂ | F15: 0 | G15: 2 | H15: 1 | J15: Melee | L15: 2 | M15: 1 | N15: 3 | X15: Presence | Z15: 4 | AB15: 4
A16: F | B16: Presence | C16: Присутствие | D16: Щит♂ | E16: ♂ | F16: 4 | G16: 8 | J16: Presence | K16: 4 | L16: 8 | N16: 12 | P16: Type | Q16: Sidereal | X16: ♃ | Y16: 1 | Z16: 3 | AB16: 4
B17: War | C17: Война | D17: Знамя♂ | E17: ♂ | J17: ♃ | K17: 11 | L17: 7 | M17: 6 | N17: 24 | Q17: =SUM(Q20:Q22)/GETPIVOTDATA("Выбор",$P$18,"Дева",Q19) -> 0.72727273 | R17: =SUM(R20:R22)/GETPIVOTDATA("Выбор",$P$18,"Дева",R19) -> 0.040816327 | S17: =SUM(S20:S22)/GETPIVOTDATA("Выбор",$P$18,"Дева",S19) -> 0.52941176 | T17: =SUM(T20:T22)/GETPIVOTDATA("Выбор",$P$18,"Дева",T19) -> 0.037037037 | U17: =SUM(U20:U22)/GETPIVOTDATA("Выбор",$P$18,"Дева",U19) -> 0.68965517 | X17: Occult | Z17: 1 | AB17: 1
B18: Investigate | C18: Расследование | D18: Ключ♃ | E18: ♃ | F18: 0 | G18: 1 | H18: 1 | J18: Investigate | L18: 1 | M18: 1 | N18: 2 | P18: Количество по полю Выбор | Q18: Названия столбцов | X18: Stealth | Y18: 1 | Z18: 2 | AB18: 3
B19: Larceny | C19: Кража | D19: Стражи♃ | E19: ♃ | F19: 0 | G19: 0 | H19: 3 | J19: Larceny | M19: 3 | N19: 3 | P19: Названия строк | Q19: Меркурий | R19: Венера | S19: Марс | T19: Юпитер | U19: Сатурн | V19: Общий итог | X19: ♄ | Z19: 5 | AB19: 5
A20: mb | B20: Lore | C20: Знания | D20: Сокровищница♃ | E20: ♃ | F20: 1 | G20: 2 | H20: 1 | J20: Lore | K20: 1 | L20: 2 | M20: 1 | N20: 4 | P20: вполне | Q20: 5 | S20: 4 | U20: 8 | V20: 17 | X20: Awareness | Z20: 3 | AB20: 3
A21: F | B21: Occult | C21: Оккультизм | D21: Чародей♃ | E21: ♃ | F21: 7 | G21: 2 | H21: 1 | J21: Occult | K21: 7 | L21: 2 | M21: 1 | N21: 10 | P21: возможно | Q21: 1 | S21: 5 | U21: 11 | V21: 17 | X21: Integrity | Z21: 1 | AB21: 1
B22: Stealth | C22: Скрытность | D22: Маска♃ | E22: ♃ | F22: 3 | G22: 2 | J22: Stealth | K22: 3 | L22: 2 | N22: 5 | P22: проблемы с гороскопами | Q22: 2 | R22: 2 | T22: 1 | U22: 1 | V22: 6 | X22: Medicine | Z22: 1 | AB22: 1
B23: Athletics | C23: Атлетика | D23: ♄Восходящий Дым | E23: ♄ | F23: 1 | G23: 0 | H23: 2 | J23: ♄ | K23: 10 | L23: 14 | M23: 2 | N23: 26 | P23: вряд ли | Q23: 2 | S23: 3 | U23: 1 | V23: 6 | X23: Дом | Y23: 1 | Z23: 1 | AB23: 2
B24: Awareness | C24: Бдительность | D24: ♄Ворон | E24: ♄ | F24: 7 | G24: 3 | J24: Athletics | K24: 1 | M24: 2 | N24: 3 | P24: (пусто) | R24: 47 | T24: 26 | V24: 73 | X24: Serenities | Y24: 1 | Z24: 1 | AB24: 2
A25: mb | B25: Bureaucracy | C25: Бюрократия | D25: ♄Телега с сеном | E25: ♄ | F25: 2 | J25: Awareness | K25: 7 | L25: 4 | N25: 11 | P25: тема не та | S25: 3 | U25: 8 | V25: 11 | X25: Общий итог | Y25: 4 | Z25: 19 | AA25: 2 | AB25: 25
A26: mb | B26: Integrity | C26: Целостность | D26: ♄Меч | E26: ♄ | F26: 0 | G26: 4 | J26: Bureaucracy | K26: 2 | N26: 2 | P26: скучно | Q26: 1 | S26: 2 | V26: 3
B27: Medicine | C27: Медицина | D27: ♄Труп | E27: ♄ | F27: 0 | G27: 6 | J27: Integrity | L27: 4 | N27: 4 | P27: Общий итог | Q27: 11 | R27: 49 | S27: 17 | T27: 27 | U27: 29 | V27: 133
B28: Battles | D28: ♂ | E28: Дом | F28: Марс | J28: Medicine | L28: 6 | N28: 6
B29: Endings | D29: ♄ | E29: Дом | F29: Сатурн | J29: Дом | K29: 9 | L29: 7 | M29: 3 | N29: 19
B30: Journeys | D30: ☿ | E30: Дом | F30: Меркурий | J30: Journeys | K30: 2 | L30: 2 | N30: 4
B31: Secrets | D31: ♃ | E31: Дом | F31: Юпитер | J31: Serenities | K31: 4 | L31: 2 | M31: 1 | N31: 7
B32: Serenities | D32: ♀ | E32: Дом | F32: Венера | J32: Battles | L32: 2 | N32: 2
J33: Secrets | L33: 1 | M33: 2 | N33: 3
J34: Endings | K34: 3 | N34: 3
J35: Общий итог | K35: 68 | L35: 51 | M35: 14 | N35: 133

Sheet Лист1
A1: Skill 1 | B1: Skill 1 | C1: Skill 2 | D1: ы | E1: Skill 3 | F1: 123 | L1: Code | M1: Ability | N1: Группы | O1: Solar Castes | P1: Siderial Castes
A2: 0 | C2: =CHAR(63+D2) -> A | D2: 2 | E2: A | F2: =A2&C2&E2 -> 0AA | H2: =CHAR(63+ROW()) -> A | L2: A | M2: Archery | N2: Dawn | O2: dawn | P2: Марс
A3: 1 | C3: =C2 -> A | D3: =D2 -> 2 | E3: B | F3: =A3&C3&E3 -> 1AB | I3: =26*25*24 -> 15600 | L3: B | M3: Athletics | N3: Bang | O3: zenith, night | P3: Сатурн
A4: 2 | C4: =C3 -> A | D4: =D3 -> 2 | E4: C | F4: =A4&C4&E4 -> 2AC | I4: =I3/6 -> 2600 | L4: C | M4: Awareness | N4: Dawn | O4: dawn, night | P4: Сатурн
A5: 3 | C5: =C4 -> A | D5: =D4 -> 2 | E5: D | F5: =A5&C5&E5 -> 3AD | L5: D | M5: Brawl | N5: Dawn | O5: dawn | P5: Марс
A6: 4 | C6: =C5 -> A | D6: =D5 -> 2 | E6: E | F6: =A6&C6&E6 -> 4AE | L6: E | M6: Bureaucracy | N6: - | O6: twilight, eclipse | P6: Сатурн
A7: 5 | C7: =C6 -> A | D7: =D6 -> 2 | E7: F | F7: =A7&C7&E7 -> 5AF | L7: F | M7: Craft | N7: Venus | O7: twilight | P7: Венера
A8: 6 | C8: =C7 -> A | D8: =D7 -> 2 | E8: G | F8: =A8&C8&E8 -> 6AG | L8: G | M8: Dodge | N8: siblings | O8: dawn, night | P8: Венера
A9: 7 | C9: =C8 -> A | D9: =D8 -> 2 | E9: H | F9: =A9&C9&E9 -> 7AH | L9: H | M9: Integrity | N9: Bang | O9: zenith, twilight | P9: Сатурн
A10: 8 | C10: =C9 -> A | D10: =D9 -> 2 | E10: I | F10: =A10&C10&E10 -> 8AI | L10: I | M10: Investigate | N10: - | O10: twilight, night | P10: Юпитер
A11: 9 | C11: =C10 -> A | D11: =D10 -> 2 | E11: J | F11: =A11&C11&E11 -> 9AJ | L11: J | M11: Larceny | N11: - | O11: night, eclipse | P11: Юпитер
A12: 10 | C12: =C11 -> A | D12: =D11 -> 2 | E12: K | F12: =A12&C12&E12 -> 10AK | L12: K | M12: Linguistics | N12: Venus | O12: twilight, eclipse | P12: Венера
A13: 11 | C13: =C12 -> A | D13: =D12 -> 2 | E13: L | F13: =A13&C13&E13 -> 11AL | L13: L | M13: Lore | N13: - | O13: zenith, twilight | P13: Юпитер
A14: 12 | C14: =C13 -> A | D14: =D13 -> 2 | E14: M | F14: =A14&C14&E14 -> 12AM | L14: M | M14: Martial Arts | N14: siblings | O14: - | P14: все
A15: 13 | C15: =C14 -> A | D15: =D14 -> 2 | E15: N | F15: =A15&C15&E15 -> 13AN | L15: N | M15: Medicine | N15: - | O15: twilight | P15: Сатурн
A16: 14 | C16: =C15 -> A | D16: =D15 -> 2 | E16: O | F16: =A16&C16&E16 -> 14AO | L16: O | M16: Melee | N16: Dawn | O16: dawn | P16: Марс
... A27: 25 | C27: =C26 -> A | D27: =D26 -> 2 | E27: Z | F27: =A27&C27&E27 -> 25AZ | L27: Z | M27: War | N27: Dawn | O27: dawn, zenith | P27: Марс
A28: 0 | C28: =CHAR(63+D28) -> B | D28: =D2+1 -> 3 | E28: =E2 -> A | F28: =A28&C28&E28 -> 0BA
A29: 1 | C29: =C28 -> B | D29: =D28 -> 3 | E29: =E3 -> B | F29: =A29&C29&E29 -> 1BB
A30: 2 | C30: =C29 -> B | D30: =D29 -> 3 | E30: =E4 -> C | F30: =A30&C30&E30 -> 2BC
A31: 3 | C31: =C30 -> B | D31: =D30 -> 3 | E31: =E5 -> D | F31: =A31&C31&E31 -> 3BD
A32: 4 | C32: =C31 -> B | D32: =D31 -> 3 | E32: =E6 -> E | F32: =A32&C32&E32 -> 4BE
A33: 5 | C33: =C32 -> B | D33: =D32 -> 3 | E33: =E7 -> F | F33: =A33&C33&E33 -> 5BF
A34: 6 | C34: =C33 -> B | D34: =D33 -> 3 | E34: =E8 -> G | F34: =A34&C34&E34 -> 6BG
A35: 7 | C35: =C34 -> B | D35: =D34 -> 3 | E35: =E9 -> H | F35: =A35&C35&E35 -> 7BH
A36: 8 | C36: =C35 -> B | D36: =D35 -> 3 | E36: =E10 -> I | F36: =A36&C36&E36 -> 8BI
A37: 9 | C37: =C36 -> B | D37: =D36 -> 3 | E37: =E11 -> J | F37: =A37&C37&E37 -> 9BJ
A38: 10 | C38: =C37 -> B | D38: =D37 -> 3 | E38: =E12 -> K | F38: =A38&C38&E38 -> 10BK
A39: 11 | C39: =C38 -> B | D39: =D38 -> 3 | E39: =E13 -> L | F39: =A39&C39&E39 -> 11BL
A40: 12 | C40: =C39 -> B | D40: =D39 -> 3 | E40: =E14 -> M | F40: =A40&C40&E40 -> 12BM
... A53: 25 | C53: =C52 -> B | D53: =D52 -> 3 | E53: =E27 -> Z | F53: =A53&C53&E53 -> 25BZ
A54: 0 | C54: =CHAR(63+D54) -> B | D54: =D53 -> 3 | E54: =E28 -> A | F54: =A54&C54&E54 -> 0BA
A55: 1 | C55: =C54 -> B | D55: =D54 -> 3 | E55: =E29 -> B | F55: =A55&C55&E55 -> 1BB
A56: 2 | C56: =C55 -> B | D56: =D55 -> 3 | E56: =E30 -> C | F56: =A56&C56&E56 -> 2BC
A57: 3 | C57: =C56 -> B | D57: =D56 -> 3 | E57: =E31 -> D | F57: =A57&C57&E57 -> 3BD
A58: 4 | C58: =C57 -> B | D58: =D57 -> 3 | E58: =E32 -> E | F58: =A58&C58&E58 -> 4BE
A59: 5 | C59: =C58 -> B | D59: =D58 -> 3 | E59: =E33 -> F | F59: =A59&C59&E59 -> 5BF
A60: 6 | C60: =C59 -> B | D60: =D59 -> 3 | E60: =E34 -> G | F60: =A60&C60&E60 -> 6BG
A61: 7 | C61: =C60 -> B | D61: =D60 -> 3 | E61: =E35 -> H | F61: =A61&C61&E61 -> 7BH
A62: 8 | C62: =C61 -> B | D62: =D61 -> 3 | E62: =E36 -> I | F62: =A62&C62&E62 -> 8BI
...

Sheet trials
A1: q | B1: color | C1: испытание | D1: блок | E1: Камни | F1: счет камня | G1: комментарий | H1: навык 1 | I1: навык 2 | J1: навык 3 | K1: н1 | L1: н2 | M1: н3 | N1: дева 1 | O1: дева 2 | P1: дева 3 | S1: блок | T1: (несколько элементов)
A2: 1 | B2: -1 | C2: 1. «Тень Героя» | D2: 45889 | E2: топаз | F2: =COUNTIF(N2:P2,E2) -> 0 | G2: неее | H2: Integrity | I2: Lore | J2: Presence | K2: =VLOOKUP(H2,Лист2!$A:$F,2,FALSE) -> 3 | L2: =VLOOKUP(I2,Лист2!$A:$F,2,FALSE) -> 0 | M2: =VLOOKUP(J2,Лист2!$A:$F,2,FALSE) -> 3 | N2: =VLOOKUP(H2,Лист2!$A:$F,6,FALSE) -> аметист | O2: =VLOOKUP(I2,Лист2!$A:$F,6,FALSE) -> изумруд | P2: =VLOOKUP(J2,Лист2!$A:$F,6,FALSE) -> рубин
A3: 4 | B3: -1 | C3: 4. «Судья и Палач» | D3: 45889 | E3: рубин | F3: =COUNTIF(N3:P3,E3) -> 2 | G3: перебор для 1 из5 испытания | H3: Socialize | I3: War | J3: Melee | K3: =VLOOKUP(H3,Лист2!$A:$F,2,FALSE) -> 0 | L3: =VLOOKUP(I3,Лист2!$A:$F,2,FALSE) -> 2 | M3: =VLOOKUP(J3,Лист2!$A:$F,2,FALSE) -> 0 | N3: =VLOOKUP(H3,Лист2!$A:$F,6,FALSE) -> сапфир | O3: =VLOOKUP(I3,Лист2!$A:$F,6,FALSE) -> рубин | P3: =VLOOKUP(J3,Лист2!$A:$F,6,FALSE) -> рубин | S3: Количество по полю испытание | T3: Названия столбцов
A4: 12 | B4: -1 | C4: 12. «Гонка на Краю» | D4: 45889 | F4: =COUNTIF(N4:P4,E4) -> 0 | G4: неее | H4: Ride | I4: Athletics | J4: Survival | K4: =VLOOKUP(H4,Лист2!$A:$F,2,FALSE) -> 0 | L4: =VLOOKUP(I4,Лист2!$A:$F,2,FALSE) -> 3 | M4: =VLOOKUP(J4,Лист2!$A:$F,2,FALSE) -> 1 | N4: =VLOOKUP(H4,Лист2!$A:$F,6,FALSE) -> топаз | O4: =VLOOKUP(I4,Лист2!$A:$F,6,FALSE) -> аметист | P4: =VLOOKUP(J4,Лист2!$A:$F,6,FALSE) -> топаз | S4: Названия строк | T4: -1 | U4: 0 | V4: 1 | W4: Общий итог
A5: 13 | B5: -1 | C5: 13. «Театр Теней» | D5: 45889 | E5: сапфир | F5: =COUNTIF(N5:P5,E5) -> 2 | G5: неее | H5: Performance | I5: Occult | J5: Socialize | K5: =VLOOKUP(H5,Лист2!$A:$F,2,FALSE) -> 0 | L5: =VLOOKUP(I5,Лист2!$A:$F,2,FALSE) -> 0 | M5: =VLOOKUP(J5,Лист2!$A:$F,2,FALSE) -> 0 | N5: =VLOOKUP(H5,Лист2!$A:$F,6,FALSE) -> сапфир | O5: =VLOOKUP(I5,Лист2!$A:$F,6,FALSE) -> изумруд | P5: =VLOOKUP(J5,Лист2!$A:$F,6,FALSE) -> сапфир | S5: (пусто) | T5: 4 | U5: 3 | W5: 7
A6: 15 | B6: -1 | C6: 15. «Пламя Лукши» | D6: 45889 | F6: =COUNTIF(N6:P6,E6) -> 0 | G6: неее | H6: Brawl | I6: Survival | J6: War | K6: =VLOOKUP(H6,Лист2!$A:$F,2,FALSE) -> 1 | L6: =VLOOKUP(I6,Лист2!$A:$F,2,FALSE) -> 1 | M6: =VLOOKUP(J6,Лист2!$A:$F,2,FALSE) -> 2 | N6: =VLOOKUP(H6,Лист2!$A:$F,6,FALSE) -> рубин | O6: =VLOOKUP(I6,Лист2!$A:$F,6,FALSE) -> топаз | P6: =VLOOKUP(J6,Лист2!$A:$F,6,FALSE) -> рубин | S6: топаз | T6: 4 | U6: 1 | V6: 3 | W6: 8
A7: 16 | B7: -1 | C7: 16. «Тень Отца» | D7: 45889 | E7: изумруд | F7: =COUNTIF(N7:P7,E7) -> 1 | G7: неее | H7: Stealth | I7: Presence | J7: Integrity | K7: =VLOOKUP(H7,Лист2!$A:$F,2,FALSE) -> 3 | L7: =VLOOKUP(I7,Лист2!$A:$F,2,FALSE) -> 3 | M7: =VLOOKUP(J7,Лист2!$A:$F,2,FALSE) -> 3 | N7: =VLOOKUP(H7,Лист2!$A:$F,6,FALSE) -> изумруд | O7: =VLOOKUP(I7,Лист2!$A:$F,6,FALSE) -> рубин | P7: =VLOOKUP(J7,Лист2!$A:$F,6,FALSE) -> аметист | S7: сапфир | T7: 2 | U7: 2 | V7: 3 | W7: 7
A8: 17 | B8: -1 | C8: 17. «Цена Свободы» | D8: 45889 | F8: =COUNTIF(N8:P8,E8) -> 0 | G8: неее | H8: Larceny | I8: Athletics | J8: Socialize | K8: =VLOOKUP(H8,Лист2!$A:$F,2,FALSE) -> 0 | L8: =VLOOKUP(I8,Лист2!$A:$F,2,FALSE) -> 3 | M8: =VLOOKUP(J8,Лист2!$A:$F,2,FALSE) -> 0 | N8: =VLOOKUP(H8,Лист2!$A:$F,6,FALSE) -> изумруд | O8: =VLOOKUP(I8,Лист2!$A:$F,6,FALSE) -> аметист | P8: =VLOOKUP(J8,Лист2!$A:$F,6,FALSE) -> сапфир | S8: рубин | T8: 4 | U8: 1 | V8: 1 | W8: 6
A9: 19 | B9: -1 | C9: 19. «Судьба Бунтаря» | D9: 45889 | F9: =COUNTIF(N9:P9,E9) -> 0 | G9: неее | H9: Investigation | I9: Occult | J9: Linguistics | K9: =VLOOKUP(H9,Лист2!$A:$F,2,FALSE) -> 0 | L9: =VLOOKUP(I9,Лист2!$A:$F,2,FALSE) -> 0 | M9: =VLOOKUP(J9,Лист2!$A:$F,2,FALSE) -> 0 | N9: =VLOOKUP(H9,Лист2!$A:$F,6,FALSE) -> изумруд | O9: =VLOOKUP(I9,Лист2!$A:$F,6,FALSE) -> изумруд | P9: =VLOOKUP(J9,Лист2!$A:$F,6,FALSE) -> сапфир | S9: изумруд | T9: 4 | U9: 2 | V9: 4 | W9: 10
A10: 20 | B10: -1 | C10: Хроники Забвения | D10: 45892 | E10: топаз | F10: =COUNTIF(N10:P10,E10) -> 0 | G10: интересно, но не для 1/5 испытаний | K10: =VLOOKUP(H10,Лист2!$A:$F,2,FALSE) -> #N/A | L10: =VLOOKUP(I10,Лист2!$A:$F,2,FALSE) -> #N/A | M10: =VLOOKUP(J10,Лист2!$A:$F,2,FALSE) -> #N/A | N10: =VLOOKUP(H10,Лист2!$A:$F,6,FALSE) -> #N/A | O10: =VLOOKUP(I10,Лист2!$A:$F,6,FALSE) -> #N/A | P10: =VLOOKUP(J10,Лист2!$A:$F,6,FALSE) -> #N/A | S10: аметист | U10: 3 | V10: 5 | W10: 8
A11: 21 | B11: -1 | C11: Симфония Безмолвия | D11: 45892 | E11: сапфир | F11: =COUNTIF(N11:P11,E11) -> 0 | G11: сложно для того, чтобы угадать | K11: =VLOOKUP(H11,Лист2!$A:$F,2,FALSE) -> #N/A | L11: =VLOOKUP(I11,Лист2!$A:$F,2,FALSE) -> #N/A | M11: =VLOOKUP(J11,Лист2!$A:$F,2,FALSE) -> #N/A | N11: =VLOOKUP(H11,Лист2!$A:$F,6,FALSE) -> #N/A | O11: =VLOOKUP(I11,Лист2!$A:$F,6,FALSE) -> #N/A | P11: =VLOOKUP(J11,Лист2!$A:$F,6,FALSE) -> #N/A | S11: Общий итог | T11: 18 | U11: 12 | V11: 16 | W11: 46
A12: 26 | B12: -1 | C12: 2. Немой Свидетель** | D12: 45894 | E12: топаз | F12: =COUNTIF(N12:P12,E12) -> 0 | G12: не | H12: Awareness | I12: Occult | J12: Linguistics | K12: =VLOOKUP(H12,Лист2!$A:$F,2,FALSE) -> 3 | L12: =VLOOKUP(I12,Лист2!$A:$F,2,FALSE) -> 0 | M12: =VLOOKUP(J12,Лист2!$A:$F,2,FALSE) -> 0 | N12: =VLOOKUP(H12,Лист2!$A:$F,6,FALSE) -> аметист | O12: =VLOOKUP(I12,Лист2!$A:$F,6,FALSE) -> изумруд | P12: =VLOOKUP(J12,Лист2!$A:$F,6,FALSE) -> сапфир
A13: 27 | B13: -1 | C13: 3. Суд Мёртвых Героев** | D13: 45894 | E13: топаз | F13: =COUNTIF(N13:P13,E13) -> 0 | G13: не.скучно | H13: Socialize | I13: Lore | J13: Integrity | K13: =VLOOKUP(H13,Лист2!$A:$F,2,FALSE) -> 0 | L13: =VLOOKUP(I13,Лист2!$A:$F,2,FALSE) -> 0 | M13: =VLOOKUP(J13,Лист2!$A:$F,2,FALSE) -> 3 | N13: =VLOOKUP(H13,Лист2!$A:$F,6,FALSE) -> сапфир | O13: =VLOOKUP(I13,Лист2!$A:$F,6,FALSE) -> изумруд | P13: =VLOOKUP(J13,Лист2!$A:$F,6,FALSE) -> аметист
A14: 34 | B14: -1 | C14: 2. Несломленный Монах (Испытание Линя)** | D14: 45894 | E14: рубин | F14: =COUNTIF(N14:P14,E14) -> 1 | G14: не, не лорно | H14: Integrity | I14: Medicine | J14: War | K14: =VLOOKUP(H14,Лист2!$A:$F,2,FALSE) -> 3 | L14: =VLOOKUP(I14,Лист2!$A:$F,2,FALSE) -> 0 | M14: =VLOOKUP(J14,Лист2!$A:$F,2,FALSE) -> 2 | N14: =VLOOKUP(H14,Лист2!$A:$F,6,FALSE) -> аметист | O14: =VLOOKUP(I14,Лист2!$A:$F,6,FALSE) -> аметист | P14: =VLOOKUP(J14,Лист2!$A:$F,6,FALSE) -> рубин
A15: 35 | B15: -1 | C15: 3. Три Удара Судьбы** | D15: 45894 | E15: рубин | F15: =COUNTIF(N15:P15,E15) -> 0 | G15: не, не лорно | H15: Resistance | I15: Integrity | J15: Linguistics | K15: =VLOOKUP(H15,Лист2!$A:$F,2,FALSE) -> 3 | L15: =VLOOKUP(I15,Лист2!$A:$F,2,FALSE) -> 3 | M15: =VLOOKUP(J15,Лист2!$A:$F,2,FALSE) -> 0 | N15: =VLOOKUP(H15,Лист2!$A:$F,6,FALSE) -> топаз | O15: =VLOOKUP(I15,Лист2!$A:$F,6,FALSE) -> аметист | P15: =VLOOKUP(J15,Лист2!$A:$F,6,FALSE) -> сапфир | S15: color | T15: 1
A16: 36 | B16: -1 | C16: Мост Трёх Шансов | D16: 45894 | E16: рубин | F16: =COUNTIF(N16:P16,E16) -> 0 | G16: не, не лорно | H16: Athletics | I16: Martial Arts | J16: Dodge | K16: =VLOOKUP(H16,Лист2!$A:$F,2,FALSE) -> 3 | L16: =VLOOKUP(I16,Лист2!$A:$F,2,FALSE) -> 5 | M16: =VLOOKUP(J16,Лист2!$A:$F,2,FALSE) -> 3 | N16: =VLOOKUP(H16,Лист2!$A:$F,6,FALSE) -> аметист | O16: =VLOOKUP(I16,Лист2!$A:$F,6,FALSE) -> все | P16: =VLOOKUP(J16,Лист2!$A:$F,6,FALSE) -> сапфир
A17: 37 | B17: -1 | C17: 1. Источник Воспоминаний** | D17: 45894 | E17: изумруд | F17: =COUNTIF(N17:P17,E17) -> 0 | G17: интересно, но не лорно!! | H17: Resistance | I17: Integrity | J17: Medicine | K17: =VLOOKUP(H17,Лист2!$A:$F,2,FALSE) -> 3 | L17: =VLOOKUP(I17,Лист2!$A:$F,2,FALSE) -> 3 | M17: =VLOOKUP(J17,Лист2!$A:$F,2,FALSE) -> 0 | N17: =VLOOKUP(H17,Лист2!$A:$F,6,FALSE) -> топаз | O17: =VLOOKUP(I17,Лист2!$A:$F,6,FALSE) -> аметист | P17: =VLOOKUP(J17,Лист2!$A:$F,6,FALSE) -> аметист | S17: Количество по полю испытание | T17: Названия столбцов
A18: 38 | B18: -1 | C18: 2. Сердце Храма** | D18: 45894 | E18: изумруд | F18: =COUNTIF(N18:P18,E18) -> 2 | G18: интересно, но не лорно!! | H18: Medicine | I18: Occult | J18: Larceny | K18: =VLOOKUP(H18,Лист2!$A:$F,2,FALSE) -> 0 | L18: =VLOOKUP(I18,Лист2!$A:$F,2,FALSE) -> 0 | M18: =VLOOKUP(J18,Лист2!$A:$F,2,FALSE) -> 0 | N18: =VLOOKUP(H18,Лист2!$A:$F,6,FALSE) -> аметист | O18: =VLOOKUP(I18,Лист2!$A:$F,6,FALSE) -> изумруд | P18: =VLOOKUP(J18,Лист2!$A:$F,6,FALSE) -> изумруд | S18: Названия строк | T18: 45889 | U18: 45892 | V18: 45894 | W18: Общий итог
A19: 39 | B19: -1 | C19: 3. Судья и Преступник** | D19: 45894 | E19: изумруд | F19: =COUNTIF(N19:P19,E19) -> 1 | G19: интересно, но не лорно!! | H19: Investigation | I19: Bureaucracy | J19: Presence | K19: =VLOOKUP(H19,Лист2!$A:$F,2,FALSE) -> 0 | L19: =VLOOKUP(I19,Лист2!$A:$F,2,FALSE) -> 0 | M19: =VLOOKUP(J19,Лист2!$A:$F,2,FALSE) -> 3 | N19: =VLOOKUP(H19,Лист2!$A:$F,6,FALSE) -> изумруд | O19: =VLOOKUP(I19,Лист2!$A:$F,6,FALSE) -> аметист | P19: =VLOOKUP(J19,Лист2!$A:$F,6,FALSE) -> рубин | S19: топаз | T19: 1 | V19: 2 | W19: 3
A20: 2 | B20: 0 | C20: 2. «Ловец Слов» | D20: 45889 | F20: =COUNTIF(N20:P20,E20) -> 0 | G20: слабо по навыкам Банга | H20: Linguistics | I20: Investigation | J20: Dodge | K20: =VLOOKUP(H20,Лист2!$A:$F,2,FALSE) -> 0 | L20: =VLOOKUP(I20,Лист2!$A:$F,2,FALSE) -> 0 | M20: =VLOOKUP(J20,Лист2!$A:$F,2,FALSE) -> 3 | N20: =VLOOKUP(H20,Лист2!$A:$F,6,FALSE) -> сапфир | O20: =VLOOKUP(I20,Лист2!$A:$F,6,FALSE) -> изумруд | P20: =VLOOKUP(J20,Лист2!$A:$F,6,FALSE) -> сапфир | S20: 1. Лабиринт Зеркальных Воспоминаний** | V20: 1 | W20: 1
A21: 3 | B21: 0 | C21: 3. «Кулаки Рассвета» | D21: 45889 | F21: =COUNTIF(N21:P21,E21) -> 0 | G21: классика, но скучно поставлено | H21: Martial Arts | I21: Brawl | J21: Resistance | K21: =VLOOKUP(H21,Лист2!$A:$F,2,FALSE) -> 5 | L21: =VLOOKUP(I21,Лист2!$A:$F,2,FALSE) -> 1 | M21: =VLOOKUP(J21,Лист2!$A:$F,2,FALSE) -> 3 | N21: =VLOOKUP(H21,Лист2!$A:$F,6,FALSE) -> все | O21: =VLOOKUP(I21,Лист2!$A:$F,6,FALSE) -> рубин | P21: =VLOOKUP(J21,Лист2!$A:$F,6,FALSE) -> топаз | S21: 1 и бегство немного перемешать | V21: 1 | W21: 1
